# Analysis of Incorrect DioException Handling

## 1. Introduction

This document outlines instances where `DioException` is handled inconsistently across the application. The standard practice, as defined in `lib/services/api_service.dart`, is to centralize Dio exception handling within the `ApiService._handleError` method. This service is designed to catch `DioException`, process it into a user-friendly error message, and then rethrow the exception.

The providers and services should catch the generic `Exception` and use the message provided by `ApiService`, rather than implementing their own logic for handling `DioException`.

---

## 2. Inconsistent Services

### 2.1. `auth_service.dart`

- **File Path**: `lib/services/auth_service.dart`

**Problem Description**:

The `AuthService` implements its own custom error handling for `DioException` through the `extractErrorMessage` method and a custom `AuthException` class. This duplicates the functionality of `ApiService` and creates a separate, inconsistent error-handling flow. Methods like `signIn`, `register`, `logout`, and `getCurrentUserProfile` all use this redundant logic.

**How to Fix**:

1.  **Remove `extractErrorMessage`**: This method is redundant. All its logic is already handled by `ApiService._handleError`.
2.  **Remove `AuthException`**: This custom exception class is also unnecessary. The providers should catch the generic `Exception` and display the error message.
3.  **Refactor `catch` blocks**: Update all `try-catch` blocks in `AuthService` to catch the generic `Exception` and rethrow it. The `ApiService` will have already processed the `DioException` and attached a user-friendly message.

**Example Refactor (`signIn` method)**:

*Before*:
```dart
// lib/services/auth_service.dart

Future<User> signIn(String email, String password) async {
  try {
    // ... API call
  } catch (e) {
    final (message, dioException) = extractErrorMessage(e);
    _logger.e('Sign-in failed: $message');
    throw AuthException(message, dioException: dioException);
  }
}
```

*After*:
```dart
// lib/services/auth_service.dart

Future<User> signIn(String email, String password) async {
  try {
    // ... API call
  } catch (e) {
    _logger.e('Sign-in failed: $e');
    rethrow; // Rethrow the exception with the message from ApiService
  }
}
```

### 2.2. `user_provider.dart`

- **File Path**: `lib/providers/user_provider.dart`

**Problem Description**:

The `UserProvider` incorrectly catches `dio.DioException` and uses `_authService.extractErrorMessage(e)` to process it, as seen in methods like `logout()`, `fetchCurrentUser()`, and `updateCurrentUserProfile()`. This creates a dependency on `AuthService` for error handling that should be managed by `ApiService`.

**How to Fix**:

1.  **Update `catch` blocks**: Modify the `catch` blocks to handle the generic `Exception` and use the `setError` method with the exception's message.

**Example Refactor (`logout` method)**:

*Before*:
```dart
// lib/providers/user_provider.dart

Future<void> logout() async {
  // ...
  try {
    // ...
  } on dio.DioException catch (e) {
    final (message, _) = _authService.extractErrorMessage(e);
    setError(message);
  } catch (e) {
    setError('Logout failed: $e');
  }
  // ...
}
```

*After*:
```dart
// lib/providers/user_provider.dart

Future<void> logout() async {
  // ...
  try {
    // ...
  } catch (e) {
    setError(e.toString());
  }
  // ...
}
```

---

*This document will be updated as more providers are analyzed.*
